[2024-06-20 10:06:48,100][flwr][INFO] - Starting Flower simulation, config: num_rounds=10, no round_timeout
[2024-06-20 10:06:50,195][flwr][INFO] - Flower VCE: Ray initialized with resources: {'node:127.0.0.1': 1.0, 'object_store_memory': 2147483648.0, 'CPU': 12.0, 'node:__internal_head__': 1.0, 'memory': 9714112922.0}
[2024-06-20 10:06:50,195][flwr][INFO] - Optimize your simulation with Flower VCE: https://flower.ai/docs/framework/how-to-run-simulations.html
[2024-06-20 10:06:50,195][flwr][INFO] - Flower VCE: Resources for each Virtual Client: {'num_cpus': 2, 'num_gpus': 0}
[2024-06-20 10:06:50,202][flwr][INFO] - Flower VCE: Creating VirtualClientEngineActorPool with 6 actors
[2024-06-20 10:06:50,202][flwr][INFO] - [INIT]
[2024-06-20 10:06:50,202][flwr][INFO] - Requesting initial parameters from one random client
[2024-06-20 10:06:52,076][flwr][INFO] - Received initial parameters from one random client
[2024-06-20 10:06:52,076][flwr][INFO] - Evaluating initial global parameters
[2024-06-20 10:06:52,509][flwr][INFO] - initial parameters (loss, other metrics): 181.76928067207336, {'accuracy': 0.1086, 'precision': 0.12349967530374152, 'recall': 0.1086, 'f1': 0.03553137346181725, 'confusion_matrix': array([[   0,    8,    0,  956,    0,    1,    0,   15,    0,    0],
       [   0,  122,    0, 1013,    0,    0,    0,    0,    0,    0],
       [   0,   38,    0,  971,    0,    0,    3,   19,    1,    0],
       [   0,   44,    0,  945,    1,    1,    0,   17,    2,    0],
       [   0,  143,    0,  816,    1,    0,    2,   20,    0,    0],
       [   0,  118,    0,  735,    1,    7,    0,   30,    1,    0],
       [   0,  144,    0,  749,   25,    0,    2,   38,    0,    0],
       [   0,  272,    0,  724,    8,    0,    0,    9,   15,    0],
       [   0,   81,    0,  859,    1,    0,    1,   32,    0,    0],
       [   0,  178,    0,  799,    1,    0,    0,   31,    0,    0]])}
[2024-06-20 10:06:52,509][flwr][INFO] - 
[2024-06-20 10:06:52,509][flwr][INFO] - [ROUND 1]
[2024-06-20 10:06:52,510][flwr][INFO] - configure_fit: strategy sampled 10 clients (out of 100)
[2024-06-20 10:06:59,516][flwr][ERROR] - Traceback (most recent call last):
  File "/opt/anaconda3/envs/flwr_env/lib/python3.8/site-packages/flwr/simulation/ray_transport/ray_client_proxy.py", line 73, in _submit_job
    out_mssg, updated_context = self.actor_pool.get_client_result(
  File "/opt/anaconda3/envs/flwr_env/lib/python3.8/site-packages/flwr/simulation/ray_transport/ray_actor.py", line 399, in get_client_result
    return self._fetch_future_result(cid)
  File "/opt/anaconda3/envs/flwr_env/lib/python3.8/site-packages/flwr/simulation/ray_transport/ray_actor.py", line 280, in _fetch_future_result
    res_cid, out_mssg, updated_context = ray.get(
  File "/opt/anaconda3/envs/flwr_env/lib/python3.8/site-packages/ray/_private/auto_init_hook.py", line 21, in auto_init_wrapper
    return fn(*args, **kwargs)
  File "/opt/anaconda3/envs/flwr_env/lib/python3.8/site-packages/ray/_private/client_mode_hook.py", line 103, in wrapper
    return func(*args, **kwargs)
  File "/opt/anaconda3/envs/flwr_env/lib/python3.8/site-packages/ray/_private/worker.py", line 2667, in get
    values, debugger_breakpoint = worker.get_objects(object_refs, timeout=timeout)
  File "/opt/anaconda3/envs/flwr_env/lib/python3.8/site-packages/ray/_private/worker.py", line 864, in get_objects
    raise value.as_instanceof_cause()
ray.exceptions.RayTaskError(TaskCancelledError): [36mray::ClientAppActor.run()[39m (pid=95920, ip=127.0.0.1, actor_id=452e359261bf2332ec1ba7a901000000, repr=<flwr.simulation.ray_transport.ray_actor.ClientAppActor object at 0x112553ac0>)
  File "/opt/anaconda3/envs/flwr_env/lib/python3.8/site-packages/flwr/simulation/ray_transport/ray_actor.py", line 58, in run
    out_message = app(message=message, context=context)
  File "/opt/anaconda3/envs/flwr_env/lib/python3.8/site-packages/flwr/client/client_app.py", line 98, in __call__
    return self._call(message, context)
  File "/opt/anaconda3/envs/flwr_env/lib/python3.8/site-packages/flwr/client/client_app.py", line 81, in ffn
    out_message = handle_legacy_message_from_msgtype(
  File "/opt/anaconda3/envs/flwr_env/lib/python3.8/site-packages/flwr/client/message_handler/message_handler.py", line 130, in handle_legacy_message_from_msgtype
    fit_res = maybe_call_fit(
  File "/opt/anaconda3/envs/flwr_env/lib/python3.8/site-packages/flwr/client/client.py", line 234, in maybe_call_fit
    return client.fit(fit_ins)
  File "/opt/anaconda3/envs/flwr_env/lib/python3.8/site-packages/flwr/client/numpy_client.py", line 238, in _fit
    results = self.numpy_client.fit(parameters, ins.config)  # type: ignore
  File "/Users/charansr/Stamp2024/client.py", line 124, in fit
    train(self.model, trainloader, optim, epochs, self.device)
  File "/Users/charansr/Stamp2024/model.py", line 44, in train
    for images, labels in trainloader:
  File "/opt/anaconda3/envs/flwr_env/lib/python3.8/site-packages/torch/utils/data/dataloader.py", line 631, in __next__
    data = self._next_data()
  File "/opt/anaconda3/envs/flwr_env/lib/python3.8/site-packages/torch/utils/data/dataloader.py", line 1318, in _next_data
    self._shutdown_workers()
  File "/opt/anaconda3/envs/flwr_env/lib/python3.8/site-packages/torch/utils/data/dataloader.py", line 1443, in _shutdown_workers
    w.join(timeout=_utils.MP_STATUS_CHECK_INTERVAL)
  File "/opt/anaconda3/envs/flwr_env/lib/python3.8/multiprocessing/process.py", line 149, in join
    res = self._popen.wait(timeout)
  File "/opt/anaconda3/envs/flwr_env/lib/python3.8/multiprocessing/popen_fork.py", line 44, in wait
    if not wait([self.sentinel], timeout):
  File "/opt/anaconda3/envs/flwr_env/lib/python3.8/multiprocessing/connection.py", line 931, in wait
    ready = selector.select(timeout)
  File "/opt/anaconda3/envs/flwr_env/lib/python3.8/selectors.py", line 415, in select
    fd_event_list = self._selector.poll(timeout)
ray.exceptions.TaskCancelledError: Task: TaskID(cdd7300817019b71452e359261bf2332ec1ba7a901000000) was cancelled.

[2024-06-20 10:06:59,517][flwr][ERROR] - Traceback (most recent call last):
  File "/opt/anaconda3/envs/flwr_env/lib/python3.8/site-packages/flwr/simulation/ray_transport/ray_client_proxy.py", line 73, in _submit_job
    out_mssg, updated_context = self.actor_pool.get_client_result(
  File "/opt/anaconda3/envs/flwr_env/lib/python3.8/site-packages/flwr/simulation/ray_transport/ray_actor.py", line 399, in get_client_result
    return self._fetch_future_result(cid)
  File "/opt/anaconda3/envs/flwr_env/lib/python3.8/site-packages/flwr/simulation/ray_transport/ray_actor.py", line 280, in _fetch_future_result
    res_cid, out_mssg, updated_context = ray.get(
  File "/opt/anaconda3/envs/flwr_env/lib/python3.8/site-packages/ray/_private/auto_init_hook.py", line 21, in auto_init_wrapper
    return fn(*args, **kwargs)
  File "/opt/anaconda3/envs/flwr_env/lib/python3.8/site-packages/ray/_private/client_mode_hook.py", line 103, in wrapper
    return func(*args, **kwargs)
  File "/opt/anaconda3/envs/flwr_env/lib/python3.8/site-packages/ray/_private/worker.py", line 2667, in get
    values, debugger_breakpoint = worker.get_objects(object_refs, timeout=timeout)
  File "/opt/anaconda3/envs/flwr_env/lib/python3.8/site-packages/ray/_private/worker.py", line 864, in get_objects
    raise value.as_instanceof_cause()
ray.exceptions.RayTaskError(TaskCancelledError): [36mray::ClientAppActor.run()[39m (pid=95923, ip=127.0.0.1, actor_id=838fdb77e31f8e29e16505c801000000, repr=<flwr.simulation.ray_transport.ray_actor.ClientAppActor object at 0x1166c7a90>)
  File "/opt/anaconda3/envs/flwr_env/lib/python3.8/site-packages/flwr/simulation/ray_transport/ray_actor.py", line 58, in run
    out_message = app(message=message, context=context)
  File "/opt/anaconda3/envs/flwr_env/lib/python3.8/site-packages/flwr/client/client_app.py", line 98, in __call__
    return self._call(message, context)
  File "/opt/anaconda3/envs/flwr_env/lib/python3.8/site-packages/flwr/client/client_app.py", line 81, in ffn
    out_message = handle_legacy_message_from_msgtype(
  File "/opt/anaconda3/envs/flwr_env/lib/python3.8/site-packages/flwr/client/message_handler/message_handler.py", line 130, in handle_legacy_message_from_msgtype
    fit_res = maybe_call_fit(
  File "/opt/anaconda3/envs/flwr_env/lib/python3.8/site-packages/flwr/client/client.py", line 234, in maybe_call_fit
    return client.fit(fit_ins)
  File "/opt/anaconda3/envs/flwr_env/lib/python3.8/site-packages/flwr/client/numpy_client.py", line 238, in _fit
    results = self.numpy_client.fit(parameters, ins.config)  # type: ignore
  File "/Users/charansr/Stamp2024/client.py", line 124, in fit
    train(self.model, trainloader, optim, epochs, self.device)
  File "/Users/charansr/Stamp2024/model.py", line 44, in train
    for images, labels in trainloader:
  File "/opt/anaconda3/envs/flwr_env/lib/python3.8/site-packages/torch/utils/data/dataloader.py", line 631, in __next__
    data = self._next_data()
  File "/opt/anaconda3/envs/flwr_env/lib/python3.8/site-packages/torch/utils/data/dataloader.py", line 1318, in _next_data
    self._shutdown_workers()
  File "/opt/anaconda3/envs/flwr_env/lib/python3.8/site-packages/torch/utils/data/dataloader.py", line 1443, in _shutdown_workers
    w.join(timeout=_utils.MP_STATUS_CHECK_INTERVAL)
  File "/opt/anaconda3/envs/flwr_env/lib/python3.8/multiprocessing/process.py", line 149, in join
    res = self._popen.wait(timeout)
  File "/opt/anaconda3/envs/flwr_env/lib/python3.8/multiprocessing/popen_fork.py", line 44, in wait
    if not wait([self.sentinel], timeout):
  File "/opt/anaconda3/envs/flwr_env/lib/python3.8/multiprocessing/connection.py", line 931, in wait
    ready = selector.select(timeout)
  File "/opt/anaconda3/envs/flwr_env/lib/python3.8/selectors.py", line 415, in select
    fd_event_list = self._selector.poll(timeout)
ray.exceptions.TaskCancelledError: Task: TaskID(1b88fc086e559b3c838fdb77e31f8e29e16505c801000000) was cancelled.

[2024-06-20 10:06:59,518][flwr][ERROR] - [36mray::ClientAppActor.run()[39m (pid=95920, ip=127.0.0.1, actor_id=452e359261bf2332ec1ba7a901000000, repr=<flwr.simulation.ray_transport.ray_actor.ClientAppActor object at 0x112553ac0>)
  File "/opt/anaconda3/envs/flwr_env/lib/python3.8/site-packages/flwr/simulation/ray_transport/ray_actor.py", line 58, in run
    out_message = app(message=message, context=context)
  File "/opt/anaconda3/envs/flwr_env/lib/python3.8/site-packages/flwr/client/client_app.py", line 98, in __call__
    return self._call(message, context)
  File "/opt/anaconda3/envs/flwr_env/lib/python3.8/site-packages/flwr/client/client_app.py", line 81, in ffn
    out_message = handle_legacy_message_from_msgtype(
  File "/opt/anaconda3/envs/flwr_env/lib/python3.8/site-packages/flwr/client/message_handler/message_handler.py", line 130, in handle_legacy_message_from_msgtype
    fit_res = maybe_call_fit(
  File "/opt/anaconda3/envs/flwr_env/lib/python3.8/site-packages/flwr/client/client.py", line 234, in maybe_call_fit
    return client.fit(fit_ins)
  File "/opt/anaconda3/envs/flwr_env/lib/python3.8/site-packages/flwr/client/numpy_client.py", line 238, in _fit
    results = self.numpy_client.fit(parameters, ins.config)  # type: ignore
  File "/Users/charansr/Stamp2024/client.py", line 124, in fit
    train(self.model, trainloader, optim, epochs, self.device)
  File "/Users/charansr/Stamp2024/model.py", line 44, in train
    for images, labels in trainloader:
  File "/opt/anaconda3/envs/flwr_env/lib/python3.8/site-packages/torch/utils/data/dataloader.py", line 631, in __next__
    data = self._next_data()
  File "/opt/anaconda3/envs/flwr_env/lib/python3.8/site-packages/torch/utils/data/dataloader.py", line 1318, in _next_data
    self._shutdown_workers()
  File "/opt/anaconda3/envs/flwr_env/lib/python3.8/site-packages/torch/utils/data/dataloader.py", line 1443, in _shutdown_workers
    w.join(timeout=_utils.MP_STATUS_CHECK_INTERVAL)
  File "/opt/anaconda3/envs/flwr_env/lib/python3.8/multiprocessing/process.py", line 149, in join
    res = self._popen.wait(timeout)
  File "/opt/anaconda3/envs/flwr_env/lib/python3.8/multiprocessing/popen_fork.py", line 44, in wait
    if not wait([self.sentinel], timeout):
  File "/opt/anaconda3/envs/flwr_env/lib/python3.8/multiprocessing/connection.py", line 931, in wait
    ready = selector.select(timeout)
  File "/opt/anaconda3/envs/flwr_env/lib/python3.8/selectors.py", line 415, in select
    fd_event_list = self._selector.poll(timeout)
ray.exceptions.TaskCancelledError: Task: TaskID(cdd7300817019b71452e359261bf2332ec1ba7a901000000) was cancelled.
[2024-06-20 10:06:59,518][flwr][ERROR] - [36mray::ClientAppActor.run()[39m (pid=95923, ip=127.0.0.1, actor_id=838fdb77e31f8e29e16505c801000000, repr=<flwr.simulation.ray_transport.ray_actor.ClientAppActor object at 0x1166c7a90>)
  File "/opt/anaconda3/envs/flwr_env/lib/python3.8/site-packages/flwr/simulation/ray_transport/ray_actor.py", line 58, in run
    out_message = app(message=message, context=context)
  File "/opt/anaconda3/envs/flwr_env/lib/python3.8/site-packages/flwr/client/client_app.py", line 98, in __call__
    return self._call(message, context)
  File "/opt/anaconda3/envs/flwr_env/lib/python3.8/site-packages/flwr/client/client_app.py", line 81, in ffn
    out_message = handle_legacy_message_from_msgtype(
  File "/opt/anaconda3/envs/flwr_env/lib/python3.8/site-packages/flwr/client/message_handler/message_handler.py", line 130, in handle_legacy_message_from_msgtype
    fit_res = maybe_call_fit(
  File "/opt/anaconda3/envs/flwr_env/lib/python3.8/site-packages/flwr/client/client.py", line 234, in maybe_call_fit
    return client.fit(fit_ins)
  File "/opt/anaconda3/envs/flwr_env/lib/python3.8/site-packages/flwr/client/numpy_client.py", line 238, in _fit
    results = self.numpy_client.fit(parameters, ins.config)  # type: ignore
  File "/Users/charansr/Stamp2024/client.py", line 124, in fit
    train(self.model, trainloader, optim, epochs, self.device)
  File "/Users/charansr/Stamp2024/model.py", line 44, in train
    for images, labels in trainloader:
  File "/opt/anaconda3/envs/flwr_env/lib/python3.8/site-packages/torch/utils/data/dataloader.py", line 631, in __next__
    data = self._next_data()
  File "/opt/anaconda3/envs/flwr_env/lib/python3.8/site-packages/torch/utils/data/dataloader.py", line 1318, in _next_data
    self._shutdown_workers()
  File "/opt/anaconda3/envs/flwr_env/lib/python3.8/site-packages/torch/utils/data/dataloader.py", line 1443, in _shutdown_workers
    w.join(timeout=_utils.MP_STATUS_CHECK_INTERVAL)
  File "/opt/anaconda3/envs/flwr_env/lib/python3.8/multiprocessing/process.py", line 149, in join
    res = self._popen.wait(timeout)
  File "/opt/anaconda3/envs/flwr_env/lib/python3.8/multiprocessing/popen_fork.py", line 44, in wait
    if not wait([self.sentinel], timeout):
  File "/opt/anaconda3/envs/flwr_env/lib/python3.8/multiprocessing/connection.py", line 931, in wait
    ready = selector.select(timeout)
  File "/opt/anaconda3/envs/flwr_env/lib/python3.8/selectors.py", line 415, in select
    fd_event_list = self._selector.poll(timeout)
ray.exceptions.TaskCancelledError: Task: TaskID(1b88fc086e559b3c838fdb77e31f8e29e16505c801000000) was cancelled.
